{
 "cells": [
  {
   "cell_type": "markdown",
   "metadata": {},
   "source": [
    "# Lesson 5a: Debugging and Error Handling\n",
    "\n",
    "[Python Debugging Handbook](https://www.freecodecamp.org/news/python-debugging-handbook/)\n",
    "\n",
    "Bugs and errors are the most common problems in programming. In this lesson we will learn how to debug and handle errors in Python.\n",
    "\n"
   ]
  },
  {
   "cell_type": "markdown",
   "metadata": {},
   "source": [
    "## 5.1. Bugs\n",
    "\n",
    "Bugs are errors in the code that make our code inoperable. Some of them are simple, some of them are hard to find and some of them are hard to fix. There are bugs that are immediately spotted by the interpreter, whilst other bugs are more difficult to find and fix because they are caused by the faulty logic of the program, or by some other external reason.\n",
    "\n",
    "Let us see the most common types of bugs/errors in Python."
   ]
  },
  {
   "cell_type": "markdown",
   "metadata": {},
   "source": [
    "### 5.1.1. Common Error Messages\n",
    "\n",
    "Python interpreter will indicate these errors to you in the form of an error message. These error messages are very helpful for debugging and fixing bugs.\n",
    "\n",
    "#### 5.1.1.1. SyntaxError - invalid syntax \n",
    "\n",
    "Syntax errors are errors in the code that you write that are caused by a syntax mistake. For example, if you write a forbidden keyword as a variable name or if you forget to close a bracket, etc. Syntax errors can be easy to find and fix. The interpreter will indicate the line where the syntax error occurred.\n"
   ]
  },
  {
   "cell_type": "code",
   "execution_count": 3,
   "metadata": {},
   "outputs": [
    {
     "ename": "SyntaxError",
     "evalue": "invalid decimal literal (1795322480.py, line 2)",
     "output_type": "error",
     "traceback": [
      "\u001b[0;36m  Cell \u001b[0;32mIn[3], line 2\u001b[0;36m\u001b[0m\n\u001b[0;31m    1name = 'John'\u001b[0m\n\u001b[0m    ^\u001b[0m\n\u001b[0;31mSyntaxError\u001b[0m\u001b[0;31m:\u001b[0m invalid decimal literal\n"
     ]
    }
   ],
   "source": [
    "# syntax error -\n",
    "1name = 'John'"
   ]
  },
  {
   "cell_type": "code",
   "execution_count": 4,
   "metadata": {},
   "outputs": [
    {
     "ename": "SyntaxError",
     "evalue": "expected ':' (2284282359.py, line 2)",
     "output_type": "error",
     "traceback": [
      "\u001b[0;36m  Cell \u001b[0;32mIn[4], line 2\u001b[0;36m\u001b[0m\n\u001b[0;31m    if 5 > 2\u001b[0m\n\u001b[0m            ^\u001b[0m\n\u001b[0;31mSyntaxError\u001b[0m\u001b[0;31m:\u001b[0m expected ':'\n"
     ]
    }
   ],
   "source": [
    "# syntax error - missing colon\n",
    "if 5 > 2\n",
    "    print(\"Five is greater than two!\")"
   ]
  },
  {
   "cell_type": "markdown",
   "metadata": {},
   "source": [
    "### 5.1.1.2. IndentationError - unexpected indent\n",
    "\n",
    "- IndentationError is another type of error in Python. An indentation error happens when you forget to use the correct indentation."
   ]
  },
  {
   "cell_type": "code",
   "execution_count": 5,
   "metadata": {},
   "outputs": [
    {
     "ename": "IndentationError",
     "evalue": "expected an indented block after 'if' statement on line 2 (1202164844.py, line 3)",
     "output_type": "error",
     "traceback": [
      "\u001b[0;36m  Cell \u001b[0;32mIn[5], line 3\u001b[0;36m\u001b[0m\n\u001b[0;31m    print(\"Five is greater than two!\")\u001b[0m\n\u001b[0m    ^\u001b[0m\n\u001b[0;31mIndentationError\u001b[0m\u001b[0;31m:\u001b[0m expected an indented block after 'if' statement on line 2\n"
     ]
    }
   ],
   "source": [
    "# indentation error\n",
    "if 5 > 2:\n",
    "print(\"Five is greater than two!\")"
   ]
  },
  {
   "cell_type": "code",
   "execution_count": 11,
   "metadata": {},
   "outputs": [
    {
     "ename": "IndentationError",
     "evalue": "unindent does not match any outer indentation level (<string>, line 3)",
     "output_type": "error",
     "traceback": [
      "\u001b[0;36m  File \u001b[0;32m<string>:3\u001b[0;36m\u001b[0m\n\u001b[0;31m    break\u001b[0m\n\u001b[0m         ^\u001b[0m\n\u001b[0;31mIndentationError\u001b[0m\u001b[0;31m:\u001b[0m unindent does not match any outer indentation level\n"
     ]
    }
   ],
   "source": [
    "for i in range(10):\n",
    "        if i == 5:\n",
    "    break"
   ]
  },
  {
   "cell_type": "markdown",
   "metadata": {},
   "source": [
    " ### 5.1.1.3. NameError - name 'variable' is not defined\n",
    "\n",
    "- A name error happens when you try to use a variable or function that has not been defined yet, or it has been deleted."
   ]
  },
  {
   "cell_type": "code",
   "execution_count": 12,
   "metadata": {},
   "outputs": [
    {
     "ename": "NameError",
     "evalue": "name 'x' is not defined",
     "output_type": "error",
     "traceback": [
      "\u001b[0;31m---------------------------------------------------------------------------\u001b[0m",
      "\u001b[0;31mNameError\u001b[0m                                 Traceback (most recent call last)",
      "Cell \u001b[0;32mIn[12], line 3\u001b[0m\n\u001b[1;32m      1\u001b[0m \u001b[38;5;66;03m# NameError: name 'x' is not defined\u001b[39;00m\n\u001b[1;32m      2\u001b[0m y \u001b[38;5;241m=\u001b[39m \u001b[38;5;241m20\u001b[39m\n\u001b[0;32m----> 3\u001b[0m \u001b[38;5;28mprint\u001b[39m(\u001b[43mx\u001b[49m \u001b[38;5;241m+\u001b[39m y)\n",
      "\u001b[0;31mNameError\u001b[0m: name 'x' is not defined"
     ]
    }
   ],
   "source": [
    "# NameError: name 'x' is not defined\n",
    "y = 20\n",
    "print(x + y)\n"
   ]
  },
  {
   "cell_type": "code",
   "execution_count": 13,
   "metadata": {},
   "outputs": [
    {
     "name": "stdout",
     "output_type": "stream",
     "text": [
      "Tom\n"
     ]
    },
    {
     "ename": "NameError",
     "evalue": "name 'name' is not defined",
     "output_type": "error",
     "traceback": [
      "\u001b[0;31m---------------------------------------------------------------------------\u001b[0m",
      "\u001b[0;31mNameError\u001b[0m                                 Traceback (most recent call last)",
      "Cell \u001b[0;32mIn[13], line 6\u001b[0m\n\u001b[1;32m      4\u001b[0m \u001b[38;5;28mprint\u001b[39m(name)\n\u001b[1;32m      5\u001b[0m \u001b[38;5;28;01mdel\u001b[39;00m name\n\u001b[0;32m----> 6\u001b[0m \u001b[38;5;28mprint\u001b[39m(\u001b[43mname\u001b[49m)\n",
      "\u001b[0;31mNameError\u001b[0m: name 'name' is not defined"
     ]
    }
   ],
   "source": [
    "# Name error - variable deleted\n",
    "\n",
    "name = 'Tom'\n",
    "print(name)\n",
    "del name\n",
    "print(name)\n"
   ]
  },
  {
   "cell_type": "markdown",
   "metadata": {},
   "source": [
    "### 5.1.1.4. AttributeError - 'object' has no attribute 'name'\n",
    "\n",
    "- An AttributeError is a type of error that happens when you try to access an attribute or method that does not exist. For example, if you try to access the length of a string, you will get an error."
   ]
  },
  {
   "cell_type": "code",
   "execution_count": 15,
   "metadata": {},
   "outputs": [
    {
     "ename": "AttributeError",
     "evalue": "'tuple' object has no attribute 'append'",
     "output_type": "error",
     "traceback": [
      "\u001b[0;31m---------------------------------------------------------------------------\u001b[0m",
      "\u001b[0;31mAttributeError\u001b[0m                            Traceback (most recent call last)",
      "Cell \u001b[0;32mIn[15], line 4\u001b[0m\n\u001b[1;32m      1\u001b[0m \u001b[38;5;66;03m# Attribute error example\u001b[39;00m\n\u001b[1;32m      3\u001b[0m my_tuple \u001b[38;5;241m=\u001b[39m (\u001b[38;5;241m1\u001b[39m, \u001b[38;5;241m2\u001b[39m, \u001b[38;5;241m3\u001b[39m)\n\u001b[0;32m----> 4\u001b[0m \u001b[43mmy_tuple\u001b[49m\u001b[38;5;241;43m.\u001b[39;49m\u001b[43mappend\u001b[49m(\u001b[38;5;241m4\u001b[39m)  \u001b[38;5;66;03m# AttributeError: 'tuple' object has no attribute 'append'\u001b[39;00m\n",
      "\u001b[0;31mAttributeError\u001b[0m: 'tuple' object has no attribute 'append'"
     ]
    }
   ],
   "source": [
    "# Attribute error example\n",
    "\n",
    "my_tuple = (1, 2, 3)\n",
    "my_tuple.append(4)  # AttributeError: 'tuple' object has no attribute 'append'\n"
   ]
  },
  {
   "cell_type": "markdown",
   "metadata": {},
   "source": [
    "### 5.1.1.5. FileNotFoundError - [Errno 2] No such file or directory: 'file'\n",
    "\n",
    "- A FileNotFoundError is a type of error that happens when you try to open a file that does not exist. For example, if you try to open a file that does not exist, you will get an error."
   ]
  },
  {
   "cell_type": "code",
   "execution_count": 17,
   "metadata": {},
   "outputs": [
    {
     "ename": "FileNotFoundError",
     "evalue": "[Errno 2] No such file or directory: 'my_file.txt'",
     "output_type": "error",
     "traceback": [
      "\u001b[0;31m---------------------------------------------------------------------------\u001b[0m",
      "\u001b[0;31mFileNotFoundError\u001b[0m                         Traceback (most recent call last)",
      "Cell \u001b[0;32mIn[17], line 3\u001b[0m\n\u001b[1;32m      1\u001b[0m \u001b[38;5;66;03m# File not found error example\u001b[39;00m\n\u001b[0;32m----> 3\u001b[0m my_file \u001b[38;5;241m=\u001b[39m \u001b[38;5;28;43mopen\u001b[39;49m\u001b[43m(\u001b[49m\u001b[38;5;124;43m'\u001b[39;49m\u001b[38;5;124;43mmy_file.txt\u001b[39;49m\u001b[38;5;124;43m'\u001b[39;49m\u001b[43m,\u001b[49m\u001b[43m \u001b[49m\u001b[38;5;124;43m'\u001b[39;49m\u001b[38;5;124;43mr\u001b[39;49m\u001b[38;5;124;43m'\u001b[39;49m\u001b[43m)\u001b[49m\n\u001b[1;32m      4\u001b[0m my_file\u001b[38;5;241m.\u001b[39mread()  \u001b[38;5;66;03m# FileNotFoundError: [Errno 2] No such file or directory: 'my_file.txt'\u001b[39;00m\n\u001b[1;32m      6\u001b[0m my_file\u001b[38;5;241m.\u001b[39mclose()\n",
      "File \u001b[0;32m~/anaconda3/envs/python312/lib/python3.12/site-packages/IPython/core/interactiveshell.py:324\u001b[0m, in \u001b[0;36m_modified_open\u001b[0;34m(file, *args, **kwargs)\u001b[0m\n\u001b[1;32m    317\u001b[0m \u001b[38;5;28;01mif\u001b[39;00m file \u001b[38;5;129;01min\u001b[39;00m {\u001b[38;5;241m0\u001b[39m, \u001b[38;5;241m1\u001b[39m, \u001b[38;5;241m2\u001b[39m}:\n\u001b[1;32m    318\u001b[0m     \u001b[38;5;28;01mraise\u001b[39;00m \u001b[38;5;167;01mValueError\u001b[39;00m(\n\u001b[1;32m    319\u001b[0m         \u001b[38;5;124mf\u001b[39m\u001b[38;5;124m\"\u001b[39m\u001b[38;5;124mIPython won\u001b[39m\u001b[38;5;124m'\u001b[39m\u001b[38;5;124mt let you open fd=\u001b[39m\u001b[38;5;132;01m{\u001b[39;00mfile\u001b[38;5;132;01m}\u001b[39;00m\u001b[38;5;124m by default \u001b[39m\u001b[38;5;124m\"\u001b[39m\n\u001b[1;32m    320\u001b[0m         \u001b[38;5;124m\"\u001b[39m\u001b[38;5;124mas it is likely to crash IPython. If you know what you are doing, \u001b[39m\u001b[38;5;124m\"\u001b[39m\n\u001b[1;32m    321\u001b[0m         \u001b[38;5;124m\"\u001b[39m\u001b[38;5;124myou can use builtins\u001b[39m\u001b[38;5;124m'\u001b[39m\u001b[38;5;124m open.\u001b[39m\u001b[38;5;124m\"\u001b[39m\n\u001b[1;32m    322\u001b[0m     )\n\u001b[0;32m--> 324\u001b[0m \u001b[38;5;28;01mreturn\u001b[39;00m \u001b[43mio_open\u001b[49m\u001b[43m(\u001b[49m\u001b[43mfile\u001b[49m\u001b[43m,\u001b[49m\u001b[43m \u001b[49m\u001b[38;5;241;43m*\u001b[39;49m\u001b[43margs\u001b[49m\u001b[43m,\u001b[49m\u001b[43m \u001b[49m\u001b[38;5;241;43m*\u001b[39;49m\u001b[38;5;241;43m*\u001b[39;49m\u001b[43mkwargs\u001b[49m\u001b[43m)\u001b[49m\n",
      "\u001b[0;31mFileNotFoundError\u001b[0m: [Errno 2] No such file or directory: 'my_file.txt'"
     ]
    }
   ],
   "source": [
    "# File not found error example\n",
    "\n",
    "my_file = open('my_file.txt', 'r')\n",
    "my_file.read()  # FileNotFoundError: [Errno 2] No such file or directory: 'my_file.txt'\n",
    "\n",
    "my_file.close()"
   ]
  },
  {
   "cell_type": "markdown",
   "metadata": {},
   "source": [
    "### 5.1.1.6. IndexError - list index out of range\n",
    "\n",
    "- An IndexError is a type of error that happens when you try to access an element in a list or tuple that is out of range.\n"
   ]
  },
  {
   "cell_type": "code",
   "execution_count": 28,
   "metadata": {},
   "outputs": [
    {
     "ename": "IndexError",
     "evalue": "list index out of range",
     "output_type": "error",
     "traceback": [
      "\u001b[0;31m---------------------------------------------------------------------------\u001b[0m",
      "\u001b[0;31mIndexError\u001b[0m                                Traceback (most recent call last)",
      "Cell \u001b[0;32mIn[28], line 4\u001b[0m\n\u001b[1;32m      1\u001b[0m \u001b[38;5;66;03m# IndexError\u001b[39;00m\n\u001b[1;32m      3\u001b[0m my_list \u001b[38;5;241m=\u001b[39m [\u001b[38;5;241m1\u001b[39m, \u001b[38;5;241m2\u001b[39m, \u001b[38;5;241m3\u001b[39m]\n\u001b[0;32m----> 4\u001b[0m \u001b[43mmy_list\u001b[49m\u001b[43m[\u001b[49m\u001b[38;5;241;43m3\u001b[39;49m\u001b[43m]\u001b[49m  \u001b[38;5;66;03m# IndexError: list index out of range\u001b[39;00m\n",
      "\u001b[0;31mIndexError\u001b[0m: list index out of range"
     ]
    }
   ],
   "source": [
    "# IndexError\n",
    "\n",
    "my_list = [1, 2, 3]\n",
    "my_list[3]  # IndexError: list index out of range"
   ]
  },
  {
   "cell_type": "markdown",
   "metadata": {},
   "source": [
    "### 5.1.1.7. ImportError - No module named 'module'\n",
    "\n",
    "- An ImportError is a type of error that happens when you try to import a module that does not exist. \n"
   ]
  },
  {
   "cell_type": "code",
   "execution_count": 18,
   "metadata": {},
   "outputs": [
    {
     "ename": "ModuleNotFoundError",
     "evalue": "No module named 'superman'",
     "output_type": "error",
     "traceback": [
      "\u001b[0;31m---------------------------------------------------------------------------\u001b[0m",
      "\u001b[0;31mModuleNotFoundError\u001b[0m                       Traceback (most recent call last)",
      "Cell \u001b[0;32mIn[18], line 2\u001b[0m\n\u001b[1;32m      1\u001b[0m \u001b[38;5;66;03m# ImportError\u001b[39;00m\n\u001b[0;32m----> 2\u001b[0m \u001b[38;5;28;01mimport\u001b[39;00m \u001b[38;5;21;01msuperman\u001b[39;00m  \u001b[38;5;66;03m# ModuleNotFoundError: No module named 'superman'\u001b[39;00m\n\u001b[1;32m      4\u001b[0m supeman\u001b[38;5;241m.\u001b[39mfly()  \u001b[38;5;66;03m# AttributeError: 'module' object has no attribute 'fly'\u001b[39;00m\n",
      "\u001b[0;31mModuleNotFoundError\u001b[0m: No module named 'superman'"
     ]
    }
   ],
   "source": [
    "# ImportError\n",
    "import superman  # ModuleNotFoundError: No module named 'superman'\n",
    "\n",
    "supeman.fly()  # AttributeError: 'module' object has no attribute 'fly'"
   ]
  },
  {
   "cell_type": "markdown",
   "metadata": {},
   "source": [
    "### 5.1.1.8. TypeError\n",
    "\n",
    "- A TypeError is a type of error that happens when you try to perform an operation that is not possible. \n",
    "    - when you want to use + operator on a string and an integer\n",
    "    - when you give a wrong number of arguments to a function\n",
    "    - when you try to call an object as if it were a function, but it's not callable. "
   ]
  },
  {
   "cell_type": "code",
   "execution_count": 19,
   "metadata": {},
   "outputs": [
    {
     "ename": "TypeError",
     "evalue": "unsupported operand type(s) for +: 'int' and 'str'",
     "output_type": "error",
     "traceback": [
      "\u001b[0;31m---------------------------------------------------------------------------\u001b[0m",
      "\u001b[0;31mTypeError\u001b[0m                                 Traceback (most recent call last)",
      "Cell \u001b[0;32mIn[19], line 5\u001b[0m\n\u001b[1;32m      3\u001b[0m x \u001b[38;5;241m=\u001b[39m \u001b[38;5;241m5\u001b[39m\n\u001b[1;32m      4\u001b[0m y \u001b[38;5;241m=\u001b[39m \u001b[38;5;124m\"\u001b[39m\u001b[38;5;124mHello\u001b[39m\u001b[38;5;124m\"\u001b[39m\n\u001b[0;32m----> 5\u001b[0m \u001b[38;5;28mprint\u001b[39m(\u001b[43mx\u001b[49m\u001b[43m \u001b[49m\u001b[38;5;241;43m+\u001b[39;49m\u001b[43m \u001b[49m\u001b[43my\u001b[49m)  \u001b[38;5;66;03m# TypeError: unsupported operand type(s) for +: 'int' and 'str'\u001b[39;00m\n",
      "\u001b[0;31mTypeError\u001b[0m: unsupported operand type(s) for +: 'int' and 'str'"
     ]
    }
   ],
   "source": [
    "# TypeError string and number\n",
    "\n",
    "x = 5\n",
    "y = \"Hello\"\n",
    "print(x + y)  # TypeError: unsupported operand type(s) for +: 'int' and 'str'"
   ]
  },
  {
   "cell_type": "code",
   "execution_count": 20,
   "metadata": {},
   "outputs": [
    {
     "ename": "TypeError",
     "evalue": "add() takes 2 positional arguments but 3 were given",
     "output_type": "error",
     "traceback": [
      "\u001b[0;31m---------------------------------------------------------------------------\u001b[0m",
      "\u001b[0;31mTypeError\u001b[0m                                 Traceback (most recent call last)",
      "Cell \u001b[0;32mIn[20], line 6\u001b[0m\n\u001b[1;32m      2\u001b[0m \u001b[38;5;28;01mdef\u001b[39;00m \u001b[38;5;21madd\u001b[39m(a, b):\n\u001b[1;32m      3\u001b[0m     \u001b[38;5;28;01mreturn\u001b[39;00m a \u001b[38;5;241m+\u001b[39m b\n\u001b[0;32m----> 6\u001b[0m \u001b[43madd\u001b[49m\u001b[43m(\u001b[49m\u001b[38;5;241;43m1\u001b[39;49m\u001b[43m,\u001b[49m\u001b[43m \u001b[49m\u001b[38;5;241;43m2\u001b[39;49m\u001b[43m,\u001b[49m\u001b[43m \u001b[49m\u001b[38;5;241;43m3\u001b[39;49m\u001b[43m)\u001b[49m\n",
      "\u001b[0;31mTypeError\u001b[0m: add() takes 2 positional arguments but 3 were given"
     ]
    }
   ],
   "source": [
    "# TypeError - wrong number of arguments in a function\n",
    "def add(a, b):\n",
    "    return a + b\n",
    "\n",
    "\n",
    "add(1, 2, 3)"
   ]
  },
  {
   "cell_type": "code",
   "execution_count": 23,
   "metadata": {},
   "outputs": [
    {
     "ename": "TypeError",
     "evalue": "'list' object is not callable",
     "output_type": "error",
     "traceback": [
      "\u001b[0;31m---------------------------------------------------------------------------\u001b[0m",
      "\u001b[0;31mTypeError\u001b[0m                                 Traceback (most recent call last)",
      "Cell \u001b[0;32mIn[23], line 4\u001b[0m\n\u001b[1;32m      1\u001b[0m \u001b[38;5;66;03m# TypeError: call non callable object\u001b[39;00m\n\u001b[1;32m      3\u001b[0m my_list \u001b[38;5;241m=\u001b[39m [\u001b[38;5;241m1\u001b[39m, \u001b[38;5;241m2\u001b[39m, \u001b[38;5;241m3\u001b[39m]\n\u001b[0;32m----> 4\u001b[0m \u001b[43mmy_list\u001b[49m\u001b[43m(\u001b[49m\u001b[43m)\u001b[49m  \u001b[38;5;66;03m# my_list is a list, not a function\u001b[39;00m\n",
      "\u001b[0;31mTypeError\u001b[0m: 'list' object is not callable"
     ]
    }
   ],
   "source": [
    "# TypeError: call non callable object\n",
    "\n",
    "my_list = [1, 2, 3]\n",
    "my_list()  # my_list is a list, not a function\n",
    "\n",
    "\n"
   ]
  },
  {
   "cell_type": "markdown",
   "metadata": {},
   "source": [
    "### 5.1.1.9. ValueError\n",
    "\n",
    "- A ValueError is a type of error that happens when you try to convert a value to a different type.\n",
    "- it can occur when you give a wrong value to a function.\n",
    "- it can also occur when you try to use mutable type as a key in a dictionary."
   ]
  },
  {
   "cell_type": "code",
   "execution_count": 24,
   "metadata": {},
   "outputs": [
    {
     "ename": "ValueError",
     "evalue": "invalid literal for int() with base 10: 'Hello'",
     "output_type": "error",
     "traceback": [
      "\u001b[0;31m---------------------------------------------------------------------------\u001b[0m",
      "\u001b[0;31mValueError\u001b[0m                                Traceback (most recent call last)",
      "Cell \u001b[0;32mIn[24], line 4\u001b[0m\n\u001b[1;32m      1\u001b[0m \u001b[38;5;66;03m# ValueError - convert non numeric string to int\u001b[39;00m\n\u001b[1;32m      3\u001b[0m my_string \u001b[38;5;241m=\u001b[39m \u001b[38;5;124m\"\u001b[39m\u001b[38;5;124mHello\u001b[39m\u001b[38;5;124m\"\u001b[39m\n\u001b[0;32m----> 4\u001b[0m \u001b[38;5;28;43mint\u001b[39;49m\u001b[43m(\u001b[49m\u001b[43mmy_string\u001b[49m\u001b[43m)\u001b[49m  \u001b[38;5;66;03m# ValueError: invalid literal for int() with base 10: 'Hello'\u001b[39;00m\n",
      "\u001b[0;31mValueError\u001b[0m: invalid literal for int() with base 10: 'Hello'"
     ]
    }
   ],
   "source": [
    "# ValueError - convert non numeric string to int\n",
    "\n",
    "my_string = \"Hello\"\n",
    "int(my_string)  # ValueError: invalid literal for int() with base 10: 'Hello'"
   ]
  },
  {
   "cell_type": "code",
   "execution_count": 27,
   "metadata": {},
   "outputs": [
    {
     "ename": "TypeError",
     "evalue": "unsupported operand type(s) for /: 'str' and 'str'",
     "output_type": "error",
     "traceback": [
      "\u001b[0;31m---------------------------------------------------------------------------\u001b[0m",
      "\u001b[0;31mTypeError\u001b[0m                                 Traceback (most recent call last)",
      "Cell \u001b[0;32mIn[27], line 6\u001b[0m\n\u001b[1;32m      2\u001b[0m \u001b[38;5;28;01mdef\u001b[39;00m \u001b[38;5;21mdivide\u001b[39m(a, b):\n\u001b[1;32m      3\u001b[0m     \u001b[38;5;28;01mreturn\u001b[39;00m a \u001b[38;5;241m/\u001b[39m b\n\u001b[0;32m----> 6\u001b[0m \u001b[43mdivide\u001b[49m\u001b[43m(\u001b[49m\u001b[38;5;124;43m'\u001b[39;49m\u001b[38;5;124;43mHello\u001b[39;49m\u001b[38;5;124;43m'\u001b[39;49m\u001b[43m,\u001b[49m\u001b[43m \u001b[49m\u001b[38;5;124;43m'\u001b[39;49m\u001b[38;5;124;43mWorld\u001b[39;49m\u001b[38;5;124;43m'\u001b[39;49m\u001b[43m)\u001b[49m  \u001b[38;5;66;03m# ValueError: unsupported operand type(s) for +: 'str' and 'str'\u001b[39;00m\n\u001b[1;32m      7\u001b[0m \u001b[38;5;66;03m# TypeError: add_two_numbers() takes 2 positional arguments but 3 were given\u001b[39;00m\n",
      "Cell \u001b[0;32mIn[27], line 3\u001b[0m, in \u001b[0;36mdivide\u001b[0;34m(a, b)\u001b[0m\n\u001b[1;32m      2\u001b[0m \u001b[38;5;28;01mdef\u001b[39;00m \u001b[38;5;21mdivide\u001b[39m(a, b):\n\u001b[0;32m----> 3\u001b[0m     \u001b[38;5;28;01mreturn\u001b[39;00m \u001b[43ma\u001b[49m\u001b[43m \u001b[49m\u001b[38;5;241;43m/\u001b[39;49m\u001b[43m \u001b[49m\u001b[43mb\u001b[49m\n",
      "\u001b[0;31mTypeError\u001b[0m: unsupported operand type(s) for /: 'str' and 'str'"
     ]
    }
   ],
   "source": [
    "# call a function with a wrong type of argument\n",
    "def divide(a, b):\n",
    "    return a / b\n",
    "\n",
    "\n",
    "divide('Hello', 'World')  # ValueError: unsupported operand type(s) for +: 'str' and 'str'\n",
    "# TypeError: add_two_numbers() takes 2 positional arguments but 3 were given"
   ]
  }
 ],
 "metadata": {
  "kernelspec": {
   "display_name": "python312",
   "language": "python",
   "name": "python3"
  },
  "language_info": {
   "codemirror_mode": {
    "name": "ipython",
    "version": 3
   },
   "file_extension": ".py",
   "mimetype": "text/x-python",
   "name": "python",
   "nbconvert_exporter": "python",
   "pygments_lexer": "ipython3",
   "version": "3.12.2"
  }
 },
 "nbformat": 4,
 "nbformat_minor": 2
}
